Workbook

Sheet old impact
A1: 15 de mayo
A2: franchise | B2: Tt_Diff_Untreated | C2: Tt_Diff_Treated | D2: Slow_ratio_Diff_Untreated | E2: Slow_ratio_Diff_Treated | F2: ctp_Diff_Untreated | G2: ctp_Diff_Treated
A3: China Wok | B3: -0.738939 | C3: -5.171122 | D3: -9.9663 | E3: -16.597 | F3: -3.76338 | G3: -7.531357
A4: KFC | B4: -0.511462 | C4: -6.731944 | D4: -3.8271 | E4: -16.2616 | F4: -2.245355 | G4: -8.407732
A5: Wendy's | B5: -0.112362 | C5: -5.802086 | D5: -5.7852 | E5: -14.5448 | F5: -2.457281 | G5: -7.005651
A7: 19 de mayo
A8: franchise | B8: Tt_Diff_Untreated | C8: Tt_Diff_Treated | D8: Slow_ratio_Diff_Untreated | E8: Slow_ratio_Diff_Treated | F8: ctp_Diff_Untreated | G8: ctp_Diff_Treated
A9: China Wok | B9: 1.200055 | C9: -10.333729 | D9: -1.743 | E9: -13.3232 | F9: 0.954033 | G9: -7.06339
A10: KFC | B10: 0.407903 | C10: -7.405832 | D10: 0.4485 | E10: -4.5119 | F10: 0.459398 | G10: -6.288985
A11: Wendy's | B11: 0.658675 | C11: -9.733286 | D11: 0.1989 | E11: -16.9151 | F11: 0.638117 | G11: -9.63949

Sheet ept_adjustment_history
A1: executed_at | B1: wave | C1: flag | D1: adjustment_scope | E1: franchise_id | F1: franchise_name | G1: vendor_code | H1: vertical_type | I1: store_name | J1: ept_old | K1: ept_change_pct | L1: ept_new | M1: ept_change_min
A2: 46247.752 | C2: Manual adjustment | D2: vendor | E2: 0011r00002VoHwaAAF | F2: Wing It - LATAM | G2: 200873 | H2: Restaurant | I2: Wing It! - Puerto Varas | J2: 8 | K2: 0.375 | L2: 11 | M2: 3
A3: 46247.752 | C3: Manual adjustment | D3: vendor | G3: 593458 | H3: Restaurant | I3: China Huo | J3: 19 | K3: 0.2632 | L3: 24 | M3: 5
A4: 46247.752 | C4: Manual adjustment | D4: vendor | G4: 625586 | H4: Restaurant | I4: Niflaot07 | J4: 8 | K4: 0.375 | L4: 11 | M4: 3
A5: 46247.752 | C5: Manual adjustment | D5: vendor | G5: 627034 | H5: Pharmacy | I5: Farmacia Skol | J5: 6 | K5: 1.1667 | L5: 13 | M5: 7
A6: 46247.752 | C6: Manual adjustment | D6: vendor | G6: 629476 | H6: Restaurant | I6: La Quinta Zona | J6: 13 | K6: 0.7692 | L6: 23 | M6: 10
A7: 46247.752 | C7: Manual adjustment | D7: vendor | G7: 630028 | H7: Courier Business | I7: Forno Di Famiglia -- | J7: 10 | K7: 1 | L7: 20 | M7: 10
A8: 46247.415 | C8: Manual adjustment | D8: vendor | E8: 0011r00002VoISxAAN | F8: Tarragona | G8: 568481 | H8: Restaurant | I8: Tarragona - Mall Centro De Concepción | J8: 3 | K8: 2.3333 | L8: 10 | M8: 7
A9: 46247.415 | C9: Manual adjustment | D9: vendor | E9: 0011r00002VoHw4AAF | F9: McDonald's | G9: 62153 | H9: Restaurant | I9: McDonald's Estación Central | J9: 1 | K9: 9 | L9: 10 | M9: 9
A10: 46241.737 | C10: Manual adjustment | D10: vendor | G10: 588253 | H10: Restaurant | I10: Delicias Quilicura | J10: 15 | K10: 0.3333 | L10: 20 | M10: 5
A11: 46241.682 | C11: Manual adjustment | D11: vendor | E11: 0011r00002VoHw2AAF | F11: KFC | G11: 325098 | H11: Courier Business | I11: KFC -- | J11: 10 | K11: 0.4 | L11: 14 | M11: 4
A12: 46241.682 | C12: Manual adjustment | D12: vendor | E12: 0011r00002VoHw2AAF | F12: KFC | G12: 521856 | H12: Courier Business | I12: KFC Libertad Viña -- | J12: 9 | K12: 0.5556 | L12: 14 | M12: 5
A13: 46241.682 | C13: Manual adjustment | D13: vendor | E13: 0011r00002VoHw2AAF | F13: KFC | G13: 521858 | H13: Courier Business | I13: KFC La Calera -- | J13: 12 | K13: 0.1667 | L13: 14 | M13: 2
A14: 46241.682 | C14: Manual adjustment | D14: vendor | E14: 0011r00002VoHw2AAF | F14: KFC | G14: 521862 | H14: Courier Business | I14: KFC Concepcion Centro -- | J14: 9 | K14: 0.5556 | L14: 14 | M14: 5
A15: 46241.682 | C15: Manual adjustment | D15: vendor | E15: 0011r00002VoHw2AAF | F15: KFC | G15: 521863 | H15: Courier Business | I15: KFC Plaza Copiapo -- | J15: 8 | K15: 0.75 | L15: 14 | M15: 6
A16: 46241.682 | C16: Manual adjustment | D16: vendor | E16: 0011r00002VoHw2AAF | F16: KFC | G16: 521864 | H16: Courier Business | I16: KFC Ovalle -- | J16: 28 | K16: -0.5 | L16: 14 | M16: -14
A17: 46241.682 | C17: Manual adjustment | D17: vendor | E17: 0011r00002VoHw2AAF | F17: KFC | G17: 521865 | H17: Courier Business | I17: KFC Alameda Uc -- | J17: 13 | K17: 0.0769 | L17: 14 | M17: 1
A18: 46241.682 | C18: Manual adjustment | D18: vendor | E18: 0011r00002VoHw2AAF | F18: KFC | G18: 522081 | H18: Courier Business | I18: KFC Serrano Castro -- | J18: 12 | K18: 0.1667 | L18: 14 | M18: 2
A19: 46241.682 | C19: Manual adjustment | D19: vendor | E19: 0011r00002VoHw2AAF | F19: KFC | G19: 522082 | H19: Courier Business | I19: KFC Iquique Sur Walmart -- | J19: 13 | K19: 0.0769 | L19: 14 | M19: 1
A20: 46241.682 | C20: Manual adjustment | D20: vendor | E20: 0011r00002VoHw2AAF | F20: KFC | G20: 522083 | H20: Courier Business | I20: KFC San Felipe -- | J20: 14 | K20: 0 | L20: 14 | M20: 0
A21: 46241.682 | C21: Manual adjustment | D21: vendor | E21: 0011r00002VoHw2AAF | F21: KFC | G21: 522086 | H21: Courier Business | I21: KFC Colina -- | J21: 9 | K21: 0.5556 | L21: 14 | M21: 5
A22: 46241.682 | C22: Manual adjustment | D22: vendor | E22: 0011r00002VoHw2AAF | F22: KFC | G22: 522087 | H22: Courier Business | I22: KFC Plaza Sur -- | J22: 14 | K22: 0 | L22: 14 | M22: 0
... A108: 46241.682 | C108: Manual adjustment | D108: vendor | E108: 0011r00002VoHw2AAF | F108: KFC | G108: 594935 | H108: Courier Business | I108: KFC Santa Cruz -- | J108: 10 | K108: 0.4 | L108: 14 | M108: 4
A109: 46239 | C109: Manual adjustment | D109: vendor | G109: 161938 | H109: Restaurant | I109: Dulce Cafe Coronel | J109: 11 | K109: 0.3636 | L109: 15 | M109: 4
A110: 46239 | C110: Manual adjustment | D110: vendor | G110: 161947 | H110: Restaurant | I110: Dulce Cafe Lagunillas | J110: 13 | K110: 0.1538 | L110: 15 | M110: 2
A111: 46239 | C111: Manual adjustment | D111: vendor | G111: 493016 | H111: Restaurant | I111: La Fontana Pastas | J111: 31 | K111: -0.5161 | L111: 15 | M111: -16
A112: 46239 | C112: Manual adjustment | D112: vendor | G112: 563357 | H112: Courier Business | I112: My Pizza -- | J112: 19 | K112: -0.4737 | L112: 10 | M112: -9
A113: 46239 | C113: Manual adjustment | D113: vendor | G113: 608793 | H113: Restaurant | I113: Factory Arica | J113: 11 | K113: 1.2727 | L113: 25 | M113: 14
A114: 46239 | C114: Manual adjustment | D114: vendor | G114: 627568 | H114: Pharmacy | I114: Farmacia Roraima Santiago Centro | J114: 6 | K114: 1 | L114: 12 | M114: 6
A115: 46239 | C115: Manual adjustment | D115: vendor | G115: 630868 | H115: Restaurant | I115: Plaza Terraza | J115: 14 | K115: 0.2143 | L115: 17 | M115: 3
A116: 46239 | C116: Manual adjustment | D116: vendor | G116: 631065 | H116: Restaurant | I116: Kata Bar & Resto | J116: 14 | K116: 0.7857 | L116: 25 | M116: 11
A117: 46265.718 | B117: Week36 | C117: AWT0 reduction | D117: vendor | E117: 0011r00002VoHwkAAF | F117: Alemán Experto | G117: 523373 | H117: MISSING | I117: Alemán Experto - Providencia | J117: 14.6 | K117: -0.3533 | L117: 9.5 | M117: -5.2
A118: 46265.718 | B118: Week36 | C118: AWT0 reduction | D118: vendor | E118: 0011r00002VoHwkAAF | F118: Alemán Experto | G118: 66806 | H118: MISSING | I118: Alemán Experto - Vitacura | J118: 20.1 | K118: -0.2611 | L118: 14.8 | M118: -5.2
A119: 46265.718 | B119: Week36 | C119: AWT0 reduction | D119: vendor | E119: 0011r00002VoHwkAAF | F119: Alemán Experto | G119: 370667 | H119: MISSING | I119: Alemán Experto Chicureo | J119: 21.2 | K119: -0.32 | L119: 14.4 | M119: -6.8
A120: 46265.718 | B120: Week36 | C120: AWT0 reduction | D120: vendor | E120: 0011r00002VoHwkAAF | F120: Alemán Experto | G120: 399367 | H120: MISSING | I120: Alemán Experto Macul | J120: 18.3 | K120: -0.3328 | L120: 12.2 | M120: -6.1
A121: 46265.718 | B121: Week36 | C121: AWT0 reduction | D121: vendor | E121: 0011r00002VoIQIAA3 | F121: American (mechado) | G121: 408558 | H121: MISSING | I121: American Burger - Coronel | J121: 17.5 | K121: -0.3727 | L121: 11 | M121: -6.5
A122: 46265.718 | B122: Week36 | C122: AWT0 reduction | D122: vendor | E122: 0011r00002VoIT9AAN | F122: Amus Buch Salads & Sandwich | G122: 132318 | H122: MISSING | I122: Amus Buch Salads & Sandwich | J122: 19.8 | K122: -0.2677 | L122: 14.5 | M122: -5.3
A123: 46265.718 | B123: Week36 | C123: AWT0 reduction | D123: vendor | E123: 0011r00002VoIQsAAN | F123: Bariloche | G123: 118766 | H123: MISSING | I123: Bariloche - Copiapó | J123: 10.2 | K123: -0.4888 | L123: 5.2 | M123: -5
A124: 46265.718 | B124: Week36 | C124: AWT0 reduction | D124: vendor | E124: 0011r00002VoIQsAAN | F124: Bariloche | G124: 101169 | H124: MISSING | I124: Bariloche- Calama | J124: 12.8 | K124: -0.4413 | L124: 7.2 | M124: -5.7
A125: 46265.718 | B125: Week36 | C125: Median Franchise-Grade | D125: vendor | E125: 0016900002nctNWAAY | F125: Barrio Chicken | G125: 624994 | H125: MISSING | I125: Barrio Chicken Costanera Center 719 | J125: 27.9 | K125: -0.6119 | L125: 10.8 | M125: -17.1
...

Sheet descripciones
A1: Wave | B1: Descripción
A2: W1 | B2: Reducción de tiempos según competencia contra Uber en Degasa
A3: W2 | B3: Reducción según median franchise a tiers 0-5 FIR, batch 1
A4: W3 | B4: Reducción según median franchise a tiers 0-5 FIR, batch 2
A5: W4 | B5: Reducción según median franchise a tiers 0-5 FIR, batch 3
A6: W5 | B6: Reducción a tiers 5-40 FIR, all batches
A7: W6 | B7: Reducciones a ecommerce targeteado por franchise - newept: oxxo, ahumada, doña carne
A8: W7 | B8: full KFC
A9: W8 | B9: Reducción según median franchise a tiers 0-50 FIR
A10: W9 | B10: Reducciones a ecommerce targeteado por franchise - newept: El Carnicero, Petrobras, Botillería Moscú
A11: W10 | B11: Cambios según tiempo fijo asignado por mcdonalds chicken-postres-general
A12: W11 | B12: Ajuste según competencia contra Uber en KFC
A13: W12 | B13: Cambios según tiempo fijo asignado por mcdonalds chicken-postres-general

Sheet recurrentes
A1: vendor_code | B1: waves_con_ajuste | C1: criterios_distintos | D1: cambio_criterio | E1: Week32 | F1: Week34 | G1: Week36
A2: 499126 | B2: 3 | C2: 1 | D2: No | E2: Median Franchise-Grade | F2: Median Franchise-Grade | G2: Median Franchise-Grade
A3: 11523 | B3: 2 | C3: 2 | D3: Sí | E3: — | F3: Median Franchise-Grade | G3: AWT0 reduction
A4: 133741 | B4: 2 | C4: 2 | D4: Sí | E4: EPT 8w ago | F4: — | G4: AWT0 reduction
A5: 133752 | B5: 2 | C5: 2 | D5: Sí | E5: EPT 8w ago | F5: — | G5: AWT0 reduction
A6: 157529 | B6: 2 | C6: 2 | D6: Sí | E6: EPT 8w ago | F6: — | G6: High preptime | FIR vertical-cuisine
A7: 205374 | B7: 2 | C7: 2 | D7: Sí | E7: EPT 8w ago | F7: Median Franchise-Grade | G7: —
A8: 264655 | B8: 2 | C8: 2 | D8: Sí | E8: Median Franchise-Grade | F8: — | G8: High preptime | FIR vertical-cuisine
A9: 319541 | B9: 2 | C9: 2 | D9: Sí | E9: — | F9: Median Franchise-Grade | G9: AWT0 reduction
A10: 355349 | B10: 2 | C10: 2 | D10: Sí | E10: EPT 8w ago | F10: — | G10: AWT0 reduction
A11: 388534 | B11: 2 | C11: 2 | D11: Sí | E11: Median Franchise-Grade | F11: — | G11: AWT0 reduction
A12: 397664 | B12: 2 | C12: 2 | D12: Sí | E12: Median Franchise-Grade | F12: — | G12: AWT0 reduction
A13: 402487 | B13: 2 | C13: 2 | D13: Sí | E13: EPT 8w ago | F13: — | G13: High preptime | FIR vertical-cuisine
... A59: 68595 | B59: 2 | C59: 1 | D59: No | E59: Median Franchise-Grade | F59: — | G59: Median Franchise-Grade

Sheet waves
A1: wave | B1: start_date | C1: franchise_name | D1: vendor_code | E1: store_name | F1: ept_old | G1: reduction | H1: ept_new | I1: diff | J1: flag
A2: W11 | B2: 2026-08-10 | C2: KFC | D2: 130023 | E2: KFC Curicó | F2: 13.3394 | G2: 0.6004318 | H2: 5.33 | I2: 8.0094
A3: W11 | B3: 2026-08-10 | C3: KFC | D3: 133550 | E3: KFC Intermodal | F3: 12.6188 | G3: 0.39376169 | H3: 7.65 | I3: 4.9688
A4: W11 | B4: 2026-08-10 | C4: KFC | D4: 135152 | E4: KFC Mall Del Centro Concepción | F4: 10.2868 | G4: 0.31757203 | H4: 7.02 | I4: 3.2668
A5: W11 | B5: 2026-08-10 | C5: KFC | D5: 140568 | E5: KFC Iquique | F5: 21.8302 | G5: 0.41961136 | H5: 12.67 | I5: 9.1602
A6: W11 | B6: 2026-08-10 | C6: KFC | D6: 153603 | E6: KFC Apumanque | F6: 11.3131 | G6: 0.35915001 | H6: 7.25 | I6: 4.0631
A7: W11 | B7: 2026-08-10 | C7: KFC | D7: 161063 | E7: KFC Chillán | H7: 17.62
A8: W11 | B8: 2026-08-10 | C8: KFC | D8: 161830 | E8: KFC San Bernardo | F8: 14.2577 | G8: 0.30353423 | H8: 9.93 | I8: 4.3277
A9: W11 | B9: 2026-08-10 | C9: KFC | D9: 166897 | E9: KFC Alto Las Condes | F9: 12.2226 | G9: 0.44938066 | H9: 6.73 | I9: 5.4926
A10: W11 | B10: 2026-08-10 | C10: KFC | D10: 181314 | E10: KFC Paseo Estacion | F10: 15.3708 | G10: 0.6701538 | H10: 5.07 | I10: 10.3008
A11: W11 | B11: 2026-08-10 | C11: KFC | D11: 186506 | E11: KFC Portal Ñuñoa | F11: 12.5318 | G11: 0.57069216 | H11: 5.38 | I11: 7.1518
A12: W11 | B12: 2026-08-10 | C12: KFC | D12: 189409 | E12: KFC Mall Arauco Quilicura | F12: 10.8463 | G12: 0.47908503 | H12: 5.65 | I12: 5.1963
A13: W11 | B13: 2026-08-10 | C13: KFC | D13: 225789 | E13: KFC Plaza Puente Alto | F13: 15.2195 | G13: 0.32980716 | H13: 10.2 | I13: 5.0195
A14: W11 | B14: 2026-08-10 | C14: KFC | D14: 234339 | E14: KFC Quillota | F14: 17.1867 | G14: 0.62354611 | H14: 6.47 | I14: 10.7167
A15: W11 | B15: 2026-08-10 | C15: KFC | D15: 272684 | E15: KFC Pedro Fontova | F15: 16.8013 | G15: 0.26196187 | H15: 12.4 | I15: 4.4013
A16: W11 | B16: 2026-08-10 | C16: KFC | D16: 308071 | E16: KFC Epacio Urbano Antofagasta | F16: 14.6153 | G16: 0.42320719 | H16: 8.43 | I16: 6.1853
A17: W11 | B17: 2026-08-10 | C17: KFC | D17: 311955 | E17: KFC Angamos | F17: 20.8704 | G17: 0.64782659 | H17: 7.35 | I17: 13.5204
A18: W11 | B18: 2026-08-10 | C18: KFC | D18: 38753 | E18: KFC Vicuña Mackenna | F18: 16.3008 | G18: 0.31782489 | H18: 11.12 | I18: 5.1808
A19: W11 | B19: 2026-08-10 | C19: KFC | D19: 38755 | E19: KFC Peñalolén | F19: 15.3577 | G19: 0.47257727 | H19: 8.1 | I19: 7.2577
... A43: W11 | B43: 2026-08-10 | C43: KFC | D43: 592065 | E43: KFC Valdivia Picarte | F43: 19.6737 | G43: 0.52576282 | H43: 9.33 | I43: 10.3437
A44: Week34 | B44: 46251 | C44: Montalbano | D44: 100004 | E44: Schopdog Calama | F44: 17.6456 | G44: 0.5006 | H44: 8.8119 | I44: 8.8337 | J44: FIR last week
A45: Week34 | B45: 46251 | D45: 100697 | E45: Food Center - Churrascos & Sandwiches | F45: 16.5841 | G45: 0.5313 | H45: 7.7733 | I45: 8.8108 | J45: EPT 8w ago
A46: Week34 | B46: 46251 | C46: Tarragona | D46: 101354 | E46: Tarragona Jumbo Puente Alto | F46: 13.378 | G46: 0.6403 | H46: 4.8121 | I46: 8.5658 | J46: FIR last week
A47: Week34 | B47: 46251 | C47: Tarragona | D47: 101365 | E47: Tarragona Mall Plaza Oeste | F47: 18.1357 | G47: 0.5844 | H47: 7.5373 | I47: 10.5984 | J47: Median Franchise-Grade
A48: Week34 | B48: 46251 | C48: Alemán Experto | D48: 102287 | E48: Aleman Experto - Pedro De Valdivia | F48: 22.7908 | G48: 0.5243 | H48: 10.8425 | I48: 11.9484 | J48: Median Franchise-Grade
A49: Week34 | B49: 46251 | C49: Tarragona | D49: 106869 | E49: Tarragona Mall Plaza Norte | F49: 21.9325 | G49: 0.6262 | H49: 8.1991 | I49: 13.7334 | J49: Median Franchise-Grade
A50: Week34 | B50: 46251 | C50: Rocoto | D50: 11523 | E50: Rocoto Las Condes | F50: 17.1388 | G50: 0.5522 | H50: 7.6749 | I50: 9.4639 | J50: Median Franchise-Grade
A51: Week34 | B51: 46251 | C51: Churromania | D51: 115870 | E51: Churromanía - Estación Central | F51: 16.665 | G51: 0.4752 | H51: 8.7454 | I51: 7.9196 | J51: Median Franchise-Grade
A52: Week34 | B52: 46251 | C52: Subway | D52: 119308 | E52: Subway Huelen | F52: 17.4112 | G52: 0.6269 | H52: 6.4959 | I52: 10.9153 | J52: Median Franchise-Grade
A53: Week34 | B53: 46251 | D53: 120974 | E53: Pizza Ninfa La Serena | F53: 33.0372 | G53: 0.3915 | H53: 20.104 | I53: 12.9332 | J53: AWT0 reduction
A54: Week34 | B54: 46251 | D54: 127845 | E54: Caracas Burger By El Arepazo | F54: 24.6059 | G54: 0.5483 | H54: 11.1133 | I54: 13.4926 | J54: High preptime | FIR vertical-cuisine
A55: Week34 | B55: 46251 | C55: Tommy Beans | D55: 128638 | E55: Tommy Beans Rancagua Mall | F55: 18.5483 | G55: 0.4528 | H55: 10.1498 | I55: 8.3985 | J55: Median Franchise-Grade
A56: Week34 | B56: 46251 | C56: Doggis | D56: 128884 | E56: Doggis Mall Plaza Maule | F56: 17.3238 | G56: 0.4517 | H56: 9.4986 | I56: 7.8252 | J56: Median Franchise-Grade
A57: Week34 | B57: 46251 | C57: Papa John's | D57: 133584 | E57: Papa Johns Pizza - Los Notros | F57: 31.4623 | G57: 0.3786 | H57: 19.5503 | I57: 11.912 | J57: Median Franchise-Grade
A58: Week34 | B58: 46251 | C58: Papa John's | D58: 133585 | E58: Papa Johns Pizza - Puerto Montt Ibañez | F58: 23.6951 | G58: 0.4205 | H58: 13.7322 | I58: 9.9629 | J58: Median Franchise-Grade
A59: Week34 | B59: 46251 | C59: Papa John's | D59: 133605 | E59: Papa Johns Pizza - Cuatro Poniente | F59: 26.0876 | G59: 0.5085 | H59: 12.8221 | I59: 13.2655 | J59: Median Franchise-Grade
A60: Week34 | B60: 46251 | C60: Papa John's | D60: 133625 | E60: Papa Johns Pizza - San Bernardo | F60: 28.2183 | G60: 0.4016 | H60: 16.8855 | I60: 11.3328 | J60: Median Franchise-Grade
A61: Week34 | B61: 46251 | C61: Papa John's | D61: 134139 | E61: Papa John's Pizza - Villa Alemana | F61: 26.8105 | G61: 0.3977 | H61: 16.1489 | I61: 10.6615 | J61: Median Franchise-Grade
A62: Week34 | B62: 46251 | C62: Doggis | D62: 137518 | E62: Doggis Lider San Joaquín | F62: 28.5169 | G62: 0.6736 | H62: 9.3076 | I62: 19.2093 | J62: Median Franchise-Grade
A63: Week34 | B63: 46251 | C63: Dunkin Donuts | D63: 139902 | E63: Dunkin' Espacio Urbano Maipú | F63: 14.8875 | G63: 0.5304 | H63: 6.9907 | I63: 7.8969 | J63: Median Franchise-Grade
...

Sheet manuales - backup
A1: franchise_id | B1: franchise_name | C1: vendor_code | D1: store_name | E1: ept_old | F1: ept_new | G1: modified_at
C2: 625929 | D2: Drift Sushi -- | F2: 35 | G2: 46225
C3: 177418 | D3: Randys Burger Oriente | F3: 13 | G3: 46225
C4: 418601 | D4: Asire Sushi | F4: 18 | G4: 46225
C5: 612209 | D5: Oleilú | F5: 20 | G5: 46225
C6: 595378 | D6: Galletrin | F6: 13 | G6: 46225
C7: 606444 | D7: Sbarro Pizza Plaza Egaña | F7: 12 | G7: 46225
C8: 606522 | D8: Sbarro Pizza Mall Plaza Norte | F8: 19 | G8: 46225
C9: 606406 | D9: Sbarro Pizza Costanera | F9: 15 | G9: 46225
C10: 613341 | D10: Vickingo | F10: 20 | G10: 46225
C11: 299049 | D11: KFC Mall La Portada | F11: 10 | G11: 46231
C12: 286542 | D12: Mi Delizie Sur Sushi | F12: 25 | G12: 46231
C13: 307148 | D13: Royal Ranch Sur | F13: 20 | G13: 46231
... C15: 592298 | D15: Macaix Acai Bowls - Temuco | F15: 10 | G15: 46231
C16: 596701 | F16: 12 | G16: 46233
A17: 0016900002dYyMCAA0 | B17: Botillería Moscú | F17: 5 | G17: 46233
A18: 0011r00002VoI36AAF | B18: Petrobras | F18: 5 | G18: 46233
A19: 0016900002f9pCnAAI | B19: El Carnicero | F19: 10 | G19: 46233
A20: 0016900002dYycoAAC | B20: Pet Perro Loco | F20: 5 | G20: 46233
C21: 161938 | D21: Dulce Cafe Coronel | E21: 10.5 | F21: 15 | G21: 46239.708
C22: 161947 | D22: Dulce Cafe Lagunillas | E22: 13.1244 | F22: 15 | G22: 46239.708
C23: 493016 | D23: La Fontana Pastas | E23: 31.1923 | F23: 15 | G23: 46239.708
C24: 563357 | D24: My Pizza -- | E24: 19 | F24: 10 | G24: 46239.708
C25: 608793 | D25: Factory Arica | E25: 10.67 | F25: 25 | G25: 46239.708
C26: 627568 | D26: Farmacia Roraima Santiago Centro | E26: 6 | F26: 12 | G26: 46239.708
C27: 630868 | D27: Plaza Terraza | E27: 14.2736 | F27: 17 | G27: 46239.708
C28: 631065 | D28: Kata Bar & Resto | E28: 14 | F28: 25 | G28: 46239.708
A29: 0011r00002VoHw2AAF | B29: KFC | C29: 325098 | D29: KFC -- | E29: 9.9734 | F29: 14 | G29: 46241.682
A30: 0011r00002VoHw2AAF | B30: KFC | C30: 521865 | D30: KFC Alameda Uc -- | E30: 12.5 | F30: 14 | G30: 46241.682
A31: 0011r00002VoHw2AAF | B31: KFC | C31: 522177 | D31: KFC Alto Las Condes -- | E31: 17 | F31: 14 | G31: 46241.682
A32: 0011r00002VoHw2AAF | B32: KFC | C32: 522175 | D32: KFC Angamos -- | E32: 20.1816 | F32: 14 | G32: 46241.682
A33: 0011r00002VoHw2AAF | B33: KFC | C33: 522158 | D33: KFC Arauco El Bosque -- | E33: 18.8909 | F33: 14 | G33: 46241.682
A34: 0011r00002VoHw2AAF | B34: KFC | C34: 522191 | D34: KFC Arica Centro -- | E34: 19 | F34: 14 | G34: 46241.682
A35: 0011r00002VoHw2AAF | B35: KFC | C35: 563239 | D35: KFC Av Alemania -- | E35: 10.1955 | F35: 14 | G35: 46241.682
A36: 0011r00002VoHw2AAF | B36: KFC | C36: 522137 | D36: KFC Balmaceda La Serena -- | E36: 8 | F36: 14 | G36: 46241.682
A37: 0011r00002VoHw2AAF | B37: KFC | C37: 522108 | D37: KFC Buenaventura -- | E37: 9 | F37: 14 | G37: 46241.682
A38: 0011r00002VoHw2AAF | B38: KFC | C38: 522145 | D38: KFC Calama -- | E38: 20.021 | F38: 14 | G38: 46241.682
A39: 0011r00002VoHw2AAF | B39: KFC | C39: 522139 | D39: KFC Centro Buin -- | E39: 10.1033 | F39: 14 | G39: 46241.682
A40: 0011r00002VoHw2AAF | B40: KFC | C40: 522157 | D40: KFC Chamisero -- | E40: 11.6 | F40: 14 | G40: 46241.682
... A83: 0011r00002VoHw2AAF | B83: KFC | C83: 522152 | D83: KFC Mid Mall -- | E83: 14.3161 | F83: 14 | G83: 46241.682
...

Sheet sample
A1: Row | B1: order_sk | C1: country_code | D1: country. country_id | E1: country. country_code | F1: country. country_iso | G1: country. country_name | H1: country. country_name_dh | I1: region | J1: order_id | K1: platform_order_id | L1: platform_order_code | M1: peya_order_id | N1: peya_partner_id | O1: entity. id | P1: entity. display_name | Q1: entity. brand_id | R1: created_date | S1: created_at | T1: created_date_local | U1: created_at_local | V1: order_placed_at | W1: order_placed_at_local | X1: city. city_id | Y1: city. city_name | Z1: city. order_value_limit | AA1: zone. zone_id | AB1: zone. zone_name | AC1: zone. geo_id | AD1: zone. is_active | AE1: zone. has_default_delivery_area_settings | AF1: zone. created_at | AG1: zone. updated_at | AH1: zone. shape | AI1: zone. delivery_types | AJ1: zone. vehicle_types | AK1: zone. distance_cap | AL1: zone. area | AM1: zone. embedding_zone_ids | AN1: zone. is_embedded | AO1: timezone | AP1: is_preorder | AQ1: estimated_prep_time | AR1: estimated_prep_buffer | AS1: cod_change_for | AT1: cod_collect_at_dropoff | AU1: cod_pay_at_pickup | AV1: delivery_fee | AW1: dropoff_address_id | AX1: online_tip | AY1: vendor_accepted_at | AZ1: vendor_accepted_at_local | BA1: sent_to_vendor_at | BB1: sent_to_vendor_at_local | BC1: original_scheduled_pickup_at | BD1: original_scheduled_pickup_at_local | BE1: pickup_address_id | BF1: platform | BG1: promised_delivery_time | BH1: promised_delivery_time_local | BI1: updated_scheduled_pickup_at | BJ1: updated_scheduled_pickup_at_local | BK1: stacking_group | BL1: order_status | BM1: tags | BN1: order_value | BO1: capacity | BP1: vendor_order_number | BQ1: deliveries. delivery_sk | BR1: deliveries. delivery_id | BS1: deliveries. created_at | BT1: deliveries. is_primary | BU1: deliveries. is_returning | BV1: deliveries. is_redelivery | BW1: deliveries. rider_id | BX1: deliveries. city_id | BY1: deliveries. timezone | BZ1: deliveries. delivery_status | CA1: deliveries. delivery_reason | CB1: deliveries. delivery_distance | CC1: deliveries. rider_dispatched_at | CD1: deliveries. rider_notified_at | CE1: deliveries. rider_accepted_at | CF1: deliveries. rider_near_restaurant_at | CG1: deliveries. rider_picked_up_at | CH1: deliveries. rider_near_customer_at | CI1: deliveries. rider_dropped_off_at | CJ1: deliveries.auto_transition. pickup | CK1: deliveries.auto_transition. dropoff | CL1: deliveries. pickup | CM1: deliveries. dropoff | CN1: deliveries. accepted | CO1: deliveries. rider_starting_point_id | CP1: deliveries. pickup_distance_manhattan | CQ1: deliveries. pickup_distance_google | CR1: deliveries. pickup_distance_dte | CS1: deliveries. dropoff_distance_dte | CT1: deliveries.estimated_distance_and_time_dte. vehicle_type | CU1: deliveries.estimated_distance_and_time_dte. time | CV1: deliveries.estimated_distance_and_time_dte. distance | CW1: deliveries. dropoff_distance_manhattan | CX1: deliveries. dropoff_distance_google | CY1: deliveries.transitions. transition_sk | CZ1: deliveries.transitions. state | DA1: deliveries.transitions. rider_id | DB1: deliveries.transitions. auto_transition | DC1: deliveries.transitions. created_at | DD1: deliveries.transitions. GEOGRAPHY | DE1: deliveries.transitions. rider_starting_point_id | DF1: deliveries.transitions.actions. user_id | DG1: deliveries.transitions.actions. performed_by | DH1: deliveries.transitions.actions. reason | DI1: deliveries.transitions.actions. issue_type | DJ1: deliveries.transitions.actions. comment | DK1: deliveries.transitions. dispatch_type | DL1: deliveries.transitions. undispatch_type | DM1: deliveries.transitions. event_type | DN1: deliveries.transitions. update_reason | DO1: deliveries.transitions. estimated_pickup_arrival_at | DP1: deliveries.transitions. estimated_dropoff_arrival_at | DQ1: deliveries.transitions. latest | DR1: deliveries.transitions. first | DS1: deliveries.transitions. created_at_local | DT1: deliveries.transitions. estimated_pickup_arrival_at_local | DU1: deliveries.transitions. estimated_dropoff_arrival_at_local | DV1: deliveries.transitions. transition_notified | DW1: deliveries.transitions. transition_accepted | DX1: deliveries.vehicle. id | DY1: deliveries.vehicle. name | DZ1: deliveries.vehicle. profile | EA1: deliveries.vehicle. vehicle_bag | EB1: deliveries.vehicle. bag_name | EC1: deliveries. stacked_deliveries | ED1: deliveries. is_stacked | EE1: deliveries. is_stacked_intravendor | EF1: deliveries.stacked_deliveries_details. delivery_id | EG1: deliveries.timings. dispatching_time | EH1: deliveries.timings. rider_reaction_time | EI1: deliveries.timings. rider_accepting_time | EJ1: deliveries.timings. to_vendor_time | EK1: deliveries.timings. vendor_arriving_time | EL1: deliveries.timings. vendor_leaving_time | EM1: deliveries.timings. rider_late | EN1: deliveries.timings. vendor_late | EO1: deliveries.timings. assumed_actual_preparation_time | EP1: deliveries.timings. bag_time | EQ1: deliveries.timings. at_vendor_time | ER1: deliveries.timings. at_vendor_time_cleaned | ES1: deliveries.timings. to_customer_time | ET1: deliveries.timings. customer_walk_in_time | EU1: deliveries.timings. at_customer_time | EV1: deliveries.timings. customer_walk_out_time | EW1: deliveries.timings. actual_delivery_time | EX1: deliveries.timings. delivery_delay | EY1: deliveries. created_at_local | EZ1: deliveries. rider_dispatched_at_local | FA1: deliveries. rider_notified_at_local | FB1: deliveries. rider_accepted_at_local | FC1: deliveries. rider_near_restaurant_at_local | FD1: deliveries. rider_picked_up_at_local | FE1: deliveries. rider_near_customer_at_local | FF1: deliveries. rider_dropped_off_at_local | FG1: deliveries.inferred_shifts. shift_sk | FH1: deliveries.inferred_shifts. shift_id | FI1: deliveries.inferred_shifts. shift_start_at | FJ1: deliveries.inferred_shifts. shift_start_at_local | FK1: deliveries.inferred_shifts. shift_end_at | FL1: deliveries.inferred_shifts. shift_end_at_local | FM1: deliveries. delivery_completed | FN1: deliveries. delivery_cancelled | FO1: cancellation. source | FP1: cancellation. performed_by | FQ1: cancellation. reason | FR1: customer. location | FS1: vendor. id | FT1: vendor. vendor_code | FU1: vendor. name | FV1: vendor. walk_in_time | FW1: vendor. walk_out_time | FX1: vendor. location | FY1: vendor. vertical_type | FZ1: porygon. vehicle_profile | GA1: porygon. drive_time_value | GB1: porygon. active_vehicle_profile | GC1: timings. updated_prep_time | GD1: timings. hold_back_time | GE1: timings. vendor_reaction_time | GF1: timings. dispatching_time | GG1: timings. rider_reaction_time | GH1: timings. rider_accepting_time | GI1: timings. to_vendor_time | GJ1: timings. expected_vendor_walk_in_time | GK1: timings. estimated_walk_in_duration | GL1: timings. estimated_walk_out_duration | GM1: timings. estimated_arriving_duration | GN1: timings. estimated_leaving_duration | GO1: timings. estimated_drop_off_duration | GP1: timings. estimated_delivery_duration_buffer | GQ1: timings. estimated_courier_delay | GR1: timings. estimated_driving_time | GS1: timings. rider_late | GT1: timings. vendor_late | GU1: timings. assumed_actual_preparation_time | GV1: timings. bag_time | GW1: timings. at_vendor_time | GX1: timings. at_vendor_time_cleaned | GY1: timings. vendor_arriving_time | GZ1: timings. vendor_leaving_time | HA1: timings. expected_vendor_walk_out_time | HB1: timings. to_customer_time | HC1: timings. customer_walk_in_time | HD1: timings. at_customer_time | HE1: timings. customer_walk_out_time | HF1: timings. actual_delivery_time | HG1: timings. promised_delivery_time | HH1: timings. order_delay | HI1: timings.zone_stats. mean_delay | HJ1: timings. avoidable_wait_time | HK1: is_order_late_10 | HL1: is_order_delay_nn | HM1: is_vendor_late_10 | HN1: is_vendor_late_nn | HO1: is_rider_late_10 | HP1: is_rider_late_nn | HQ1: order_completed | HR1: primary_delivery_rider_dropped_off_at_local | HS1: order_completed_np | HT1: order_cancelled | HU1: to_dispatch_time | HV1: prepared_at | HW1: audi_load_date | HX1: utilization_type | HY1: awt_id | HZ1: food_is_ready_at
A2: 1 | B2: 7e9ee7dff9a6aa03b94aa59b0ac93ab35f71e5725faa75478218ae59756c51e1 | C2: uy | D2: 1 | E2: uy | F2: UY | G2: Uruguay | H2: Uruguay | I2: Americas | J2: 3 | K2: 26268 | L2: 30443255 | M2: 30443255 | N2: 42 | O2: PY_UY | P2: PY - Uruguay | Q2: PY | R2: 42894 | S2: 2017-06-08 18:11:26.867000 UTC | T2: 42894 | U2: 42894.633 | V2: 2017-06-08 18:11:26.007000 UTC | W2: 42894.633 | X2: 1 | Y2: Montevideo | Z2: 250000 | AA2: 1 | AB2: Sur | AC2: sur | AD2: TRUE | AE2: TRUE | AF2: 2018-10-18 15:23:19.096459 UTC | AG2: 2024-02-02 06:13:06.982388 UTC | AH2: POLYGON((-56.2140641 -34.9105614, -56.2122131 -34.9116604, -56.2102171 -34.9121354, -56.2083561 -34.9116524, -56.2046171 -34.9106924, -56.2019351 -34.9106574, -56.1979871 -34.9120654, -56.1939951 -34.9128924, -56.1868931 -34.9158484, -56.1847041 -34.9160594, -56.1827301 -34.9156194, -56.1792541 -34.9150914, -56.1760141 -34.9148454, -56.1730311 -34.9148454, -56.1706071 -34.9152504, -56.1695601 -34.9179874, -56.1709711 -34.9190684, -56.1725033259964 -34.9198274320558, -56.1721694547292 -34.9207211460853, -56.1711226473097 -34.9214802015123, -56.1712534946916 -34.9228167898634, -56.1717219910535 -34.9231528641264, -56.1720383981293 -34.9243939260158, -56.171549069129 -34.9252213453885, -56.1707141 -34.9251734, -56.1692331 -34.9252964, -56.1669371 -34.9260524, -56.1621791 -34.9293174, -56.1605481 -34.9308304, -56.1607631 -34.9325544, -56.1637241 -34.9325194, -56.1636811 -34.9331174, -56.1616641 -34.9340674, -56.1607201 -34.9353684, -56.1605051 -34.9364944, -56.1599901 -34.9378314, -56.1587891 -34.9334334, -56.1587891 -34.9287194, -56.1577101 -34.9275654, -56.1538101 -34.9250594, -56.1496911 -34.9222444, -56.1455711 -34.9201334, -56.1455711 -34.9190074, -56.1481831 -34.9182934, -56.1482481 -34.9162524, -56.1472821 -34.9141944, -56.1425401 -34.9105874, -56.1402491 -34.9112654, -56.1383611 -34.9121104, -56.1357861 -34.9109844, -56.1330391 -34.9122514, -56.1308081 -34.9116884, -56.1300091 -34.9110444, -56.1296061 -34.9098584, -56.1328681 -34.9090134, -56.1331411 -34.9077544, -56.1318381 -34.9047904, -56.1275461 -34.9059164, -56.1257281 -34.9054404, -56.1239251 -34.9046304, -56.1231501 -34.9021994, -56.121892 -34.8998624, -56.1200952516811 -34.8986910838319, -56.1165761947632 -34.8976175481557, -56.1138939857483 -34.898251111891, -56.1117696762085 -34.897406359158, -56.1122417449951 -34.896526398082, -56.1187219619751 -34.8871806425717, -56.1239790916443 -34.8868814197189, -56.1314464503675 -34.8798409383652, -56.1385488510132 -34.8739610065961, -56.1558651911037 -34.874805999307, -56.1743831634522 -34.88110797066, -56.1859703063965 -34.8811959835985, -56.1971743 -34.8833678, -56.1981582641602 -34.8879726968254, -56.196870803833 -34.8981807161617, -56.1991291 -34.8995814, -56.2030506134033 -34.9005741371092, -56.2091445922852 -34.9026155292723, -56.2160968780518 -34.9051496006743, -56.2140641 -34.9105614)) | AI2: 0 rows | AJ2: 0 rows | AK2: null | AL2: 31.33 | AM2: 0 rows | AN2: FALSE | AO2: America/Montevideo | AP2: FALSE | AQ2: 900 | AR2: 300 | AS2: 0 | AT2: 900000 | AU2: 900000 | AV2: 0 | AW2: 5 | AX2: 0 | AY2: null | AZ2: null | BA2: null | BB2: null | BC2: null | BD2: null | BE2: 2 | BF2: PEDIDOS_YA | BG2: 2017-06-08 18:41:26.016000 UTC | BH2: 42894.654 | BI2: 2017-06-08 18:28:38.885000 UTC | BJ2: 42894.645 | BK2: null | BL2: cancelled | BM2: 0 rows | BN2: 900000 | BO2: 100 | BP2: null | BQ2: d0b3cde4da48d13eee5fc116f42ad774b1b299b96319515c77b8c166e98e8121 | BR2: 3 | BS2: 2017-06-08 18:11:26.881000 UTC | BT2: TRUE | BU2: null | BV2: FALSE | BW2: null | BX2: 1 | BY2: America/Montevideo | BZ2: completed | CA2: null | CB2: 708 | CC2: 2017-06-08 18:11:55.357000 UTC | CD2: null | CE2: 2017-06-08 18:13:38.880000 UTC | CF2: null | CG2: 2017-06-08 19:42:28.052000 UTC | CH2: null | CI2: 2017-06-08 19:42:33.520000 UTC | CJ2: null | CK2: null | CL2: null | CM2: null | CN2: null | CO2: 1 | CP2: null | CQ2: null | CR2: null | CS2: null | CT2: null | CU2: null | CV2: null | CW2: null | CX2: null | CY2: 8a2ae010dcf7adc7ca8e05268b03ee34931fee3211cd86e3b44f8e635bb7b012 | CZ2: completed | DA2: null | DB2: null | DC2: 2017-06-08 19:42:33.518000 UTC | DD2: null | DE2: 1 | DF2: null | DG2: null | DH2: null | DI2: null | DJ2: null | DK2: null | DL2: null | DM2: null | DN2: null | DO2: null | DP2: null | DQ2: TRUE | DR2: TRUE | DS2: 42894.696 | DT2: null | DU2: null | DV2: 0 | DW2: 0 | DX2: null | DY2: null | DZ2: null | EA2: null | EB2: null | EC2: 0 | ED2: FALSE | EE2: FALSE | EF2: null | EG2: 0 | EH2: null | EI2: 0 | EJ2: 0 | EK2: 0 | EL2: 0 | EM2: null | EN2: null | EO2: null | EP2: null | EQ2: 0 | ER2: 0 | ES2: 0 | ET2: 0 | EU2: 0 | EV2: 0 | EW2: 0 | EX2: null | EY2: 42894.633 | EZ2: 42894.633 | FA2: null | FB2: 42894.634 | FC2: null | FD2: 42894.696 | FE2: null | FF2: 42894.696 | FG2: null | FH2: null | FI2: null | FJ2: null | FK2: null | FL2: null | FM2: 1 | FN2: 0 | FO2: dispatcher | FP2: 12132 | FQ2: null | FR2: CG2M3HUKIEBYLZXEQOM1TCN3QQUJYQ3DMGJCPFHJ | FS2: 1 | FT2: 42 | FU2: Empanadaspeia | FV2: null | FW2: null | FX2: POINT(-56.1996002197266 -34.9057006835938) | FY2: restaurants | FZ2: null | GA2: null | GB2: null | GC2: 0 | GD2: 0 | GE2: 0 | GF2: 0 | GG2: null | GH2: 0 | GI2: 0 | GJ2: null | GK2: null | GL2: null | GM2: null | GN2: null | GO2: null | GP2: null | GQ2: null | GR2: null | GS2: null | GT2: null | GU2: null | GV2: null | GW2: 0 | GX2: 0 | GY2: 0 | GZ2: 0 | HA2: null | HB2: 0 | HC2: 0 | HD2: 0 | HE2: 0 | HF2: 0 | HG2: 1800 | HH2: null | HI2: null | HJ2: null | HK2: 0 | HL2: 0 | HM2: 0 | HN2: 0 | HO2: 0 | HP2: 0 | HQ2: 1 | HR2: 42894.696 | HS2: 1 | HT2: 1 | HU2: 132 | HV2: null | HW2: 45324.94 | HX2: null | HY2: null | HZ2: null
BQ3: 685ddcf7d1b3bde6b86abcac8fced5c5cc1e5dd0ee6f98a7cef1c5ebcce0ef5f | BR3: 4 | BS3: 2017-06-08 18:11:55.447000 UTC | BT3: FALSE | BU3: null | BV3: FALSE | BW3: null | BX3: 1 | BY3: America/Montevideo | BZ3: cancelled | CA3: null | CB3: 708 | CC3: null | CD3: null | CE3: null | CF3: null | CG3: null | CH3: null | CI3: null | CJ3: null | CK3: null | CL3: null | CM3: null | CN3: null | CO3: null | CP3: null | CQ3: null | CR3: null | CS3: null | CT3: null | CU3: null | CV3: null | CW3: null | CX3: null | CY3: 141a0ab4e644e15cc81407218ac3037141a938489ad4f2d73b23970dc84ada9a | CZ3: cancelled | DA3: null | DB3: null | DC3: 2017-06-08 20:00:58.590000 UTC | DD3: null | DE3: null | DF3: null | DG3: order_state_machine | DH3: null | DI3: null | DJ3: null | DK3: null | DL3: order_cancelled | DM3: null | DN3: null | DO3: null | DP3: null | DQ3: TRUE | DR3: TRUE | DS3: 42894.709 | DT3: null | DU3: null | DV3: 0 | DW3: 0 | DX3: null | DY3: null | DZ3: null | EA3: null | EB3: null | EC3: null | ED3: FALSE | EE3: null | EF3: null | EG3: 0 | EH3: null | EI3: 0 | EJ3: 0 | EK3: 0 | EL3: 0 | EM3: null | EN3: null | EO3: null | EP3: null | EQ3: 0 | ER3: 0 | ES3: 0 | ET3: 0 | EU3: 0 | EV3: 0 | EW3: 0 | EX3: null | EY3: 42894.633 | EZ3: null | FA3: null | FB3: null | FC3: null | FD3: null | FE3: null | FF3: null | FG3: null | FH3: null | FI3: null | FJ3: null | FK3: null | FL3: null | FM3: 0 | FN3: 1
A4: 2 | B4: 442f9d14b283dac622d63dfae12aaa37decaa1e09f11ce2f9175b98798a1534b | C4: uy | D4: 1 | E4: uy | F4: UY | G4: Uruguay | H4: Uruguay | I4: Americas | J4: 5 | K4: 26322 | L4: 30444252 | M4: 30444252 | N4: 42 | O4: PY_UY | P4: PY - Uruguay | Q4: PY | R4: 42894 | S4: 2017-06-08 19:43:57.626000 UTC | T4: 42894 | U4: 42894.697 | V4: 2017-06-08 19:43:56.630000 UTC | W4: 42894.697 | X4: 1 | Y4: Montevideo | Z4: 250000 | AA4: 1 | AB4: Sur | AC4: sur | AD4: TRUE | AE4: TRUE | AF4: 2018-10-18 15:23:19.096459 UTC | AG4: 2024-02-02 06:13:06.982388 UTC | AH4: POLYGON((-56.2140641 -34.9105614, -56.2122131 -34.9116604, -56.2102171 -34.9121354, -56.2083561 -34.9116524, -56.2046171 -34.9106924, -56.2019351 -34.9106574, -56.1979871 -34.9120654, -56.1939951 -34.9128924, -56.1868931 -34.9158484, -56.1847041 -34.9160594, -56.1827301 -34.9156194, -56.1792541 -34.9150914, -56.1760141 -34.9148454, -56.1730311 -34.9148454, -56.1706071 -34.9152504, -56.1695601 -34.9179874, -56.1709711 -34.9190684, -56.1725033259964 -34.9198274320558, -56.1721694547292 -34.9207211460853, -56.1711226473097 -34.9214802015123, -56.1712534946916 -34.9228167898634, -56.1717219910535 -34.9231528641264, -56.1720383981293 -34.9243939260158, -56.171549069129 -34.9252213453885, -56.1707141 -34.9251734, -56.1692331 -34.9252964, -56.1669371 -34.9260524, -56.1621791 -34.9293174, -56.1605481 -34.9308304, -56.1607631 -34.9325544, -56.1637241 -34.9325194, -56.1636811 -34.9331174, -56.1616641 -34.9340674, -56.1607201 -34.9353684, -56.1605051 -34.9364944, -56.1599901 -34.9378314, -56.1587891 -34.9334334, -56.1587891 -34.9287194, -56.1577101 -34.9275654, -56.1538101 -34.9250594, -56.1496911 -34.9222444, -56.1455711 -34.9201334, -56.1455711 -34.9190074, -56.1481831 -34.9182934, -56.1482481 -34.9162524, -56.1472821 -34.9141944, -56.1425401 -34.9105874, -56.1402491 -34.9112654, -56.1383611 -34.9121104, -56.1357861 -34.9109844, -56.1330391 -34.9122514, -56.1308081 -34.9116884, -56.1300091 -34.9110444, -56.1296061 -34.9098584, -56.1328681 -34.9090134, -56.1331411 -34.9077544, -56.1318381 -34.9047904, -56.1275461 -34.9059164, -56.1257281 -34.9054404, -56.1239251 -34.9046304, -56.1231501 -34.9021994, -56.121892 -34.8998624, -56.1200952516811 -34.8986910838319, -56.1165761947632 -34.8976175481557, -56.1138939857483 -34.898251111891, -56.1117696762085 -34.897406359158, -56.1122417449951 -34.896526398082, -56.1187219619751 -34.8871806425717, -56.1239790916443 -34.8868814197189, -56.1314464503675 -34.8798409383652, -56.1385488510132 -34.8739610065961, -56.1558651911037 -34.874805999307, -56.1743831634522 -34.88110797066, -56.1859703063965 -34.8811959835985, -56.1971743 -34.8833678, -56.1981582641602 -34.8879726968254, -56.196870803833 -34.8981807161617, -56.1991291 -34.8995814, -56.2030506134033 -34.9005741371092, -56.2091445922852 -34.9026155292723, -56.2160968780518 -34.9051496006743, -56.2140641 -34.9105614)) | AI4: 0 rows | AJ4: 0 rows | AK4: null | AL4: 31.33 | AM4: 0 rows | AN4: FALSE | AO4: America/Montevideo | AP4: FALSE | AQ4: 900 | AR4: 300 | AS4: 0 | AT4: 21500 | AU4: 21500 | AV4: 0 | AW4: 7 | AX4: 0 | AY4: null | AZ4: null | BA4: null | BB4: null | BC4: null | BD4: null | BE4: 2 | BF4: PEDIDOS_YA | BG4: 2017-06-08 20:13:56.655000 UTC | BH4: 42894.718 | BI4: 2017-06-08 20:07:14.524000 UTC | BJ4: 42894.713 | BK4: null | BL4: cancelled | BM4: 0 rows | BN4: 21500 | BO4: 9 | BP4: null | BQ4: 83c1a92111a7293f3094c1ce9aef4ee2c3f29e9b835dd6e3a65f69f8e532dd86 | BR4: 6 | BS4: 2017-06-08 19:43:57.644000 UTC | BT4: TRUE | BU4: null | BV4: FALSE | BW4: null | BX4: 1 | BY4: America/Montevideo | BZ4: cancelled | CA4: null | CB4: 708 | CC4: 2017-06-08 19:51:36.186000 UTC | CD4: null | CE4: 2017-06-08 19:52:14.519000 UTC | CF4: null | CG4: null | CH4: null | CI4: null | CJ4: null | CK4: null | CL4: null | CM4: null | CN4: null | CO4: null | CP4: null | CQ4: null | CR4: null | CS4: null | CT4: null | CU4: null | CV4: null | CW4: null | CX4: null | CY4: 624850905ef554ee1db3c3a31765b018211cd99e7ea9a186f8d0e624d2e55316 | CZ4: cancelled | DA4: null | DB4: null | DC4: 2017-06-08 20:01:09.529000 UTC | DD4: null | DE4: null | DF4: null | DG4: order_state_machine | DH4: null | DI4: null | DJ4: null | DK4: null | DL4: order_cancelled | DM4: null | DN4: null | DO4: 2017-06-08 20:56:38 UTC | DP4: 2017-06-08 21:01:17 UTC | DQ4: TRUE | DR4: TRUE | DS4: 42894.709 | DT4: 42894.748 | DU4: 42894.751 | DV4: 0 | DW4: 0 | DX4: null | DY4: null | DZ4: null | EA4: null | EB4: null | EC4: null | ED4: FALSE | EE4: null | EF4: null | EG4: 0 | EH4: null | EI4: 0 | EJ4: 0 | EK4: 0 | EL4: 0 | EM4: null | EN4: null | EO4: null | EP4: null | EQ4: 0 | ER4: 0 | ES4: 0 | ET4: 0 | EU4: 0 | EV4: 0 | EW4: 0 | EX4: null | EY4: 42894.697 | EZ4: 42894.703 | FA4: null | FB4: 42894.703 | FC4: null | FD4: null | FE4: null | FF4: null | FG4: null | FH4: null | FI4: null | FJ4: null | FK4: null | FL4: null | FM4: 0 | FN4: 1 | FO4: dispatcher | FP4: 12132 | FQ4: null | FR4: CG2M3HUKIEBYLZXEQOM1TCN3QQUJYQ3DMGJCPFHJ | FS4: 1 | FT4: 42 | FU4: Empanadaspeia | FV4: null | FW4: null | FX4: POINT(-56.1996002197266 -34.9057006835938) | FY4: restaurants | FZ4: null | GA4: null | GB4: null | GC4: 0 | GD4: 0 | GE4: 0 | GF4: 0 | GG4: null | GH4: 0 | GI4: 0 | GJ4: null | GK4: null | GL4: null | GM4: null | GN4: null | GO4: null | GP4: null | GQ4: null | GR4: null | GS4: null | GT4: null | GU4: null | GV4: null | GW4: 0 | GX4: 0 | GY4: 0 | GZ4: 0 | HA4: null | HB4: 0 | HC4: 0 | HD4: 0 | HE4: 0 | HF4: 0 | HG4: 1800 | HH4: null | HI4: null | HJ4: null | HK4: 0 | HL4: 0 | HM4: 0 | HN4: 0 | HO4: 0 | HP4: 0 | HQ4: 0 | HR4: null | HS4: 0 | HT4: 1 | HU4: 497 | HV4: null | HW4: 45324.94 | HX4: null | HY4: null | HZ4: null
A5: 3 | B5: d293c447fd51080209855011f18d8fe402104dd82326efe4998531fe393b9224 | C5: uy | D5: 1 | E5: uy | F5: UY | G5: Uruguay | H5: Uruguay | I5: Americas | J5: 4 | K5: 26299 | L5: 30443920 | M5: 30443920 | N5: 42 | O5: PY_UY | P5: PY - Uruguay | Q5: PY | R5: 42894 | S5: 2017-06-08 19:03:49.903000 UTC | T5: 42894 | U5: 42894.669 | V5: 2017-06-08 19:03:48.933000 UTC | W5: 42894.669 | X5: 1 | Y5: Montevideo | Z5: 250000 | AA5: 1 | AB5: Sur | AC5: sur | AD5: TRUE | AE5: TRUE | AF5: 2018-10-18 15:23:19.096459 UTC | AG5: 2024-02-02 06:13:06.982388 UTC | AH5: POLYGON((-56.2140641 -34.9105614, -56.2122131 -34.9116604, -56.2102171 -34.9121354, -56.2083561 -34.9116524, -56.2046171 -34.9106924, -56.2019351 -34.9106574, -56.1979871 -34.9120654, -56.1939951 -34.9128924, -56.1868931 -34.9158484, -56.1847041 -34.9160594, -56.1827301 -34.9156194, -56.1792541 -34.9150914, -56.1760141 -34.9148454, -56.1730311 -34.9148454, -56.1706071 -34.9152504, -56.1695601 -34.9179874, -56.1709711 -34.9190684, -56.1725033259964 -34.9198274320558, -56.1721694547292 -34.9207211460853, -56.1711226473097 -34.9214802015123, -56.1712534946916 -34.9228167898634, -56.1717219910535 -34.9231528641264, -56.1720383981293 -34.9243939260158, -56.171549069129 -34.9252213453885, -56.1707141 -34.9251734, -56.1692331 -34.9252964, -56.1669371 -34.9260524, -56.1621791 -34.9293174, -56.1605481 -34.9308304, -56.1607631 -34.9325544, -56.1637241 -34.9325194, -56.1636811 -34.9331174, -56.1616641 -34.9340674, -56.1607201 -34.9353684, -56.1605051 -34.9364944, -56.1599901 -34.9378314, -56.1587891 -34.9334334, -56.1587891 -34.9287194, -56.1577101 -34.9275654, -56.1538101 -34.9250594, -56.1496911 -34.9222444, -56.1455711 -34.9201334, -56.1455711 -34.9190074, -56.1481831 -34.9182934, -56.1482481 -34.9162524, -56.1472821 -34.9141944, -56.1425401 -34.9105874, -56.1402491 -34.9112654, -56.1383611 -34.9121104, -56.1357861 -34.9109844, -56.1330391 -34.9122514, -56.1308081 -34.9116884, -56.1300091 -34.9110444, -56.1296061 -34.9098584, -56.1328681 -34.9090134, -56.1331411 -34.9077544, -56.1318381 -34.9047904, -56.1275461 -34.9059164, -56.1257281 -34.9054404, -56.1239251 -34.9046304, -56.1231501 -34.9021994, -56.121892 -34.8998624, -56.1200952516811 -34.8986910838319, -56.1165761947632 -34.8976175481557, -56.1138939857483 -34.898251111891, -56.1117696762085 -34.897406359158, -56.1122417449951 -34.896526398082, -56.1187219619751 -34.8871806425717, -56.1239790916443 -34.8868814197189, -56.1314464503675 -34.8798409383652, -56.1385488510132 -34.8739610065961, -56.1558651911037 -34.874805999307, -56.1743831634522 -34.88110797066, -56.1859703063965 -34.8811959835985, -56.1971743 -34.8833678, -56.1981582641602 -34.8879726968254, -56.196870803833 -34.8981807161617, -56.1991291 -34.8995814, -56.2030506134033 -34.9005741371092, -56.2091445922852 -34.9026155292723, -56.2160968780518 -34.9051496006743, -56.2140641 -34.9105614)) | AI5: 0 rows | AJ5: 0 rows | AK5: null | AL5: 31.33 | AM5: 0 rows | AN5: FALSE | AO5: America/Montevideo | AP5: FALSE | AQ5: 900 | AR5: 300 | AS5: 0 | AT5: 21500 | AU5: 21500 | AV5: 0 | AW5: 6 | AX5: 0 | AY5: null | AZ5: null | BA5: null | BB5: null | BC5: null | BD5: null | BE5: 2 | BF5: PEDIDOS_YA | BG5: 2017-06-08 19:33:48.946000 UTC | BH5: 42894.69 | BI5: null | BJ5: null | BK5: null | BL5: cancelled | BM5: 0 rows | BN5: 21500 | BO5: 9 | BP5: null | BQ5: 7038e9fdd672dd07faaa386795857d5c09f9ee953f89bc1f2184e0338dea776b | BR5: 5 | BS5: 2017-06-08 19:03:49.921000 UTC | BT5: TRUE | BU5: null | BV5: FALSE | BW5: null | BX5: 1 | BY5: America/Montevideo | BZ5: cancelled | CA5: null | CB5: 708 | CC5: 2017-06-08 19:54:12.375000 UTC | CD5: null | CE5: null | CF5: null | CG5: null | CH5: null | CI5: null | CJ5: null | CK5: null | CL5: null | CM5: null | CN5: null | CO5: null | CP5: null | CQ5: null | CR5: null | CS5: null | CT5: null | CU5: null | CV5: null | CW5: null | CX5: null | CY5: 96668074857641c99085459d3b70323efcad33dae966ff4135cb30da9800f9b9 | CZ5: cancelled | DA5: null | DB5: null | DC5: 2017-06-08 20:00:49.011000 UTC | DD5: null | DE5: null | DF5: null | DG5: order_state_machine | DH5: null | DI5: null | DJ5: null | DK5: null | DL5: order_cancelled | DM5: null | DN5: null | DO5: 2017-06-08 21:06:48 UTC | DP5: 2017-06-08 21:16:27 UTC | DQ5: TRUE | DR5: TRUE | DS5: 42894.709 | DT5: 42894.755 | DU5: 42894.761 | DV5: 0 | DW5: 0 | DX5: null | DY5: null | DZ5: null | EA5: null | EB5: null | EC5: null | ED5: FALSE | EE5: null | EF5: null | EG5: 0 | EH5: null | EI5: 0 | EJ5: 0 | EK5: 0 | EL5: 0 | EM5: null | EN5: null | EO5: null | EP5: null | EQ5: 0 | ER5: 0 | ES5: 0 | ET5: 0 | EU5: 0 | EV5: 0 | EW5: 0 | EX5: null | EY5: 42894.669 | EZ5: 42894.704 | FA5: null | FB5: null | FC5: null | FD5: null | FE5: null | FF5: null | FG5: null | FH5: null | FI5: null | FJ5: null | FK5: null | FL5: null | FM5: 0 | FN5: 1 | FO5: dispatcher | FP5: 12132 | FQ5: null | FR5: CG2M3HUKIEBYLZXEQOM1TCN3QQUJYQ3DMGJCPFHJ | FS5: 1 | FT5: 42 | FU5: Empanadaspeia | FV5: null | FW5: null | FX5: POINT(-56.1996002197266 -34.9057006835938) | FY5: restaurants | FZ5: null | GA5: null | GB5: null | GC5: 0 | GD5: 0 | GE5: 0 | GF5: 0 | GG5: null | GH5: 0 | GI5: 0 | GJ5: null | GK5: null | GL5: null | GM5: null | GN5: null | GO5: null | GP5: null | GQ5: null | GR5: null | GS5: null | GT5: null | GU5: null | GV5: null | GW5: 0 | GX5: 0 | GY5: 0 | GZ5: 0 | HA5: null | HB5: 0 | HC5: 0 | HD5: 0 | HE5: 0 | HF5: 0 | HG5: 1800 | HH5: null | HI5: null | HJ5: null | HK5: 0 | HL5: 0 | HM5: 0 | HN5: 0 | HO5: 0 | HP5: 0 | HQ5: 0 | HR5: null | HS5: 0 | HT5: 1 | HU5: null | HV5: null | HW5: 45324.94 | HX5: null | HY5: null | HZ5: null
A6: 4 | B6: ee1a2acf16cd9660517084e72eeed7304f071167c60ebd7600d7e911296952cd | C6: uy | D6: 1 | E6: uy | F6: UY | G6: Uruguay | H6: Uruguay | I6: Americas | J6: 6 | K6: 26334 | L6: 30444373 | M6: 30444373 | N6: 42 | O6: PY_UY | P6: PY - Uruguay | Q6: PY | R6: 42894 | S6: 2017-06-08 20:01:53.227000 UTC | T6: 42894 | U6: 42894.71 | V6: 2017-06-08 20:01:52.056000 UTC | W6: 42894.71 | X6: 1 | Y6: Montevideo | Z6: 250000 | AA6: 1 | AB6: Sur | AC6: sur | AD6: TRUE | AE6: TRUE | AF6: 2018-10-18 15:23:19.096459 UTC | AG6: 2024-02-02 06:13:06.982388 UTC | AH6: POLYGON((-56.2140641 -34.9105614, -56.2122131 -34.9116604, -56.2102171 -34.9121354, -56.2083561 -34.9116524, -56.2046171 -34.9106924, -56.2019351 -34.9106574, -56.1979871 -34.9120654, -56.1939951 -34.9128924, -56.1868931 -34.9158484, -56.1847041 -34.9160594, -56.1827301 -34.9156194, -56.1792541 -34.9150914, -56.1760141 -34.9148454, -56.1730311 -34.9148454, -56.1706071 -34.9152504, -56.1695601 -34.9179874, -56.1709711 -34.9190684, -56.1725033259964 -34.9198274320558, -56.1721694547292 -34.9207211460853, -56.1711226473097 -34.9214802015123, -56.1712534946916 -34.9228167898634, -56.1717219910535 -34.9231528641264, -56.1720383981293 -34.9243939260158, -56.171549069129 -34.9252213453885, -56.1707141 -34.9251734, -56.1692331 -34.9252964, -56.1669371 -34.9260524, -56.1621791 -34.9293174, -56.1605481 -34.9308304, -56.1607631 -34.9325544, -56.1637241 -34.9325194, -56.1636811 -34.9331174, -56.1616641 -34.9340674, -56.1607201 -34.9353684, -56.1605051 -34.9364944, -56.1599901 -34.9378314, -56.1587891 -34.9334334, -56.1587891 -34.9287194, -56.1577101 -34.9275654, -56.1538101 -34.9250594, -56.1496911 -34.9222444, -56.1455711 -34.9201334, -56.1455711 -34.9190074, -56.1481831 -34.9182934, -56.1482481 -34.9162524, -56.1472821 -34.9141944, -56.1425401 -34.9105874, -56.1402491 -34.9112654, -56.1383611 -34.9121104, -56.1357861 -34.9109844, -56.1330391 -34.9122514, -56.1308081 -34.9116884, -56.1300091 -34.9110444, -56.1296061 -34.9098584, -56.1328681 -34.9090134, -56.1331411 -34.9077544, -56.1318381 -34.9047904, -56.1275461 -34.9059164, -56.1257281 -34.9054404, -56.1239251 -34.9046304, -56.1231501 -34.9021994, -56.121892 -34.8998624, -56.1200952516811 -34.8986910838319, -56.1165761947632 -34.8976175481557, -56.1138939857483 -34.898251111891, -56.1117696762085 -34.897406359158, -56.1122417449951 -34.896526398082, -56.1187219619751 -34.8871806425717, -56.1239790916443 -34.8868814197189, -56.1314464503675 -34.8798409383652, -56.1385488510132 -34.8739610065961, -56.1558651911037 -34.874805999307, -56.1743831634522 -34.88110797066, -56.1859703063965 -34.8811959835985, -56.1971743 -34.8833678, -56.1981582641602 -34.8879726968254, -56.196870803833 -34.8981807161617, -56.1991291 -34.8995814, -56.2030506134033 -34.9005741371092, -56.2091445922852 -34.9026155292723, -56.2160968780518 -34.9051496006743, -56.2140641 -34.9105614)) | AI6: 0 rows | AJ6: 0 rows | AK6: null | AL6: 31.33 | AM6: 0 rows | AN6: FALSE | AO6: America/Montevideo | AP6: FALSE | AQ6: 900 | AR6: 300 | AS6: 0 | AT6: 25500 | AU6: 25500 | AV6: 0 | AW6: 8 | AX6: 0 | AY6: null | AZ6: null | BA6: null | BB6: null | BC6: null | BD6: null | BE6: 2 | BF6: PEDIDOS_YA | BG6: 2017-06-08 20:31:52.077000 UTC | BH6: 42894.73 | BI6: 2017-06-08 20:30:47.005000 UTC | BJ6: 42894.73 | BK6: null | BL6: completed | BM6: 0 rows | BN6: 25500 | BO6: 11 | BP6: null | BQ6: b10ba0dd3ac0993cc8addf86c3d561baaa3645a2209fc5c689823017bc6c8956 | BR6: 7 | BS6: 2017-06-08 20:01:53.246000 UTC | BT6: TRUE | BU6: null | BV6: FALSE | BW6: null | BX6: 1 | BY6: America/Montevideo | BZ6: completed | CA6: null | CB6: 708 | CC6: 2017-06-08 20:01:57.132000 UTC | CD6: null | CE6: 2017-06-08 20:15:46.999000 UTC | CF6: null | CG6: 2017-06-08 20:15:50.496000 UTC | CH6: null | CI6: 2017-06-08 20:15:55.916000 UTC | CJ6: null | CK6: null | CL6: null | CM6: null | CN6: null | CO6: 1 | CP6: null | CQ6: null | CR6: null | CS6: null | CT6: null | CU6: null | CV6: null | CW6: null | CX6: null | CY6: 24f71a26679dccf7f940a39d4453def46a0a33f1f7fa1f4234f8fc5400ea2b8d | CZ6: completed | DA6: null | DB6: null | DC6: 2017-06-08 20:15:55.913000 UTC | DD6: null | DE6: 1 | DF6: null | DG6: null | DH6: null | DI6: null | DJ6: null | DK6: null | DL6: null | DM6: null | DN6: null | DO6: null | DP6: null | DQ6: TRUE | DR6: TRUE | DS6: 42894.719 | DT6: null | DU6: null | DV6: 0 | DW6: 0 | DX6: null | DY6: null | DZ6: null | EA6: null | EB6: null | EC6: 0 | ED6: FALSE | EE6: FALSE | EF6: null | EG6: 0 | EH6: null | EI6: 0 | EJ6: 0 | EK6: 0 | EL6: 0 | EM6: null | EN6: null | EO6: null | EP6: null | EQ6: 0 | ER6: 0 | ES6: 0 | ET6: 0 | EU6: 0 | EV6: 0 | EW6: 0 | EX6: null | EY6: 42894.71 | EZ6: 42894.71 | FA6: null | FB6: 42894.719 | FC6: null | FD6: 42894.719 | FE6: null | FF6: 42894.719 | FG6: null | FH6: null | FI6: null | FJ6: null | FK6: null | FL6: null | FM6: 1 | FN6: 0 | FO6: null | FP6: null | FQ6: null | FR6: CG2M3HUKIEBYLZXEQOM1TCN3QQUJYQ3DMGJCPFHJ | FS6: 1 | FT6: 42 | FU6: Empanadaspeia | FV6: null | FW6: null | FX6: POINT(-56.1996002197266 -34.9057006835938) | FY6: restaurants | FZ6: null | GA6: null | GB6: null | GC6: 0 | GD6: 0 | GE6: 0 | GF6: 0 | GG6: null | GH6: 0 | GI6: 0 | GJ6: null | GK6: null | GL6: null | GM6: null | GN6: null | GO6: null | GP6: null | GQ6: null | GR6: null | GS6: null | GT6: null | GU6: null | GV6: null | GW6: 0 | GX6: 0 | GY6: 0 | GZ6: 0 | HA6: null | HB6: 0 | HC6: 0 | HD6: 0 | HE6: 0 | HF6: 0 | HG6: 1800 | HH6: null | HI6: null | HJ6: null | HK6: 0 | HL6: 0 | HM6: 0 | HN6: 0 | HO6: 0 | HP6: 0 | HQ6: 1 | HR6: 42894.719 | HS6: 1 | HT6: 0 | HU6: 834 | HV6: null | HW6: 45324.94 | HX6: null | HY6: null | HZ6: null
A7: 5 | B7: 166844d2c711b13c6bb18be667e5c0d2918e73a611dacf7434983034f663b2c3 | C7: uy | D7: 1 | E7: uy | F7: UY | G7: Uruguay | H7: Uruguay | I7: Americas | J7: 1 | K7: 26225 | L7: 30441588 | M7: 30441588 | N7: 42 | O7: PY_UY | P7: PY - Uruguay | Q7: PY | R7: 42894 | S7: 2017-06-08 17:02:33.651000 UTC | T7: 42894 | U7: 42894.585 | V7: 2017-06-08 17:02:32.357000 UTC | W7: 42894.585 | X7: 1 | Y7: Montevideo | Z7: 250000 | AA7: 1 | AB7: Sur | AC7: sur | AD7: TRUE | AE7: TRUE | AF7: 2018-10-18 15:23:19.096459 UTC | AG7: 2024-02-02 06:13:06.982388 UTC | AH7: POLYGON((-56.2140641 -34.9105614, -56.2122131 -34.9116604, -56.2102171 -34.9121354, -56.2083561 -34.9116524, -56.2046171 -34.9106924, -56.2019351 -34.9106574, -56.1979871 -34.9120654, -56.1939951 -34.9128924, -56.1868931 -34.9158484, -56.1847041 -34.9160594, -56.1827301 -34.9156194, -56.1792541 -34.9150914, -56.1760141 -34.9148454, -56.1730311 -34.9148454, -56.1706071 -34.9152504, -56.1695601 -34.9179874, -56.1709711 -34.9190684, -56.1725033259964 -34.9198274320558, -56.1721694547292 -34.9207211460853, -56.1711226473097 -34.9214802015123, -56.1712534946916 -34.9228167898634, -56.1717219910535 -34.9231528641264, -56.1720383981293 -34.9243939260158, -56.171549069129 -34.9252213453885, -56.1707141 -34.9251734, -56.1692331 -34.9252964, -56.1669371 -34.9260524, -56.1621791 -34.9293174, -56.1605481 -34.9308304, -56.1607631 -34.9325544, -56.1637241 -34.9325194, -56.1636811 -34.9331174, -56.1616641 -34.9340674, -56.1607201 -34.9353684, -56.1605051 -34.9364944, -56.1599901 -34.9378314, -56.1587891 -34.9334334, -56.1587891 -34.9287194, -56.1577101 -34.9275654, -56.1538101 -34.9250594, -56.1496911 -34.9222444, -56.1455711 -34.9201334, -56.1455711 -34.9190074, -56.1481831 -34.9182934, -56.1482481 -34.9162524, -56.1472821 -34.9141944, -56.1425401 -34.9105874, -56.1402491 -34.9112654, -56.1383611 -34.9121104, -56.1357861 -34.9109844, -56.1330391 -34.9122514, -56.1308081 -34.9116884, -56.1300091 -34.9110444, -56.1296061 -34.9098584, -56.1328681 -34.9090134, -56.1331411 -34.9077544, -56.1318381 -34.9047904, -56.1275461 -34.9059164, -56.1257281 -34.9054404, -56.1239251 -34.9046304, -56.1231501 -34.9021994, -56.121892 -34.8998624, -56.1200952516811 -34.8986910838319, -56.1165761947632 -34.8976175481557, -56.1138939857483 -34.898251111891, -56.1117696762085 -34.897406359158, -56.1122417449951 -34.896526398082, -56.1187219619751 -34.8871806425717, -56.1239790916443 -34.8868814197189, -56.1314464503675 -34.8798409383652, -56.1385488510132 -34.8739610065961, -56.1558651911037 -34.874805999307, -56.1743831634522 -34.88110797066, -56.1859703063965 -34.8811959835985, -56.1971743 -34.8833678, -56.1981582641602 -34.8879726968254, -56.196870803833 -34.8981807161617, -56.1991291 -34.8995814, -56.2030506134033 -34.9005741371092, -56.2091445922852 -34.9026155292723, -56.2160968780518 -34.9051496006743, -56.2140641 -34.9105614)) | AI7: 0 rows | AJ7: 0 rows | AK7: null | AL7: 31.33 | AM7: 0 rows | AN7: FALSE | AO7: America/Montevideo | AP7: FALSE | AQ7: 900 | AR7: 300 | AS7: 0 | AT7: 900000 | AU7: 900000 | AV7: 0 | AW7: 3 | AX7: 0 | AY7: 2017-06-08 17:28:20.996000 UTC | AZ7: 42894.603 | BA7: 2017-06-08 17:27:51.726000 UTC | BB7: 42894.603 | BC7: null | BD7: null | BE7: 2 | BF7: PEDIDOS_YA | BG7: 2017-06-08 17:32:32.368000 UTC | BH7: 42894.606 | BI7: 2017-06-08 17:28:51.726000 UTC | BJ7: 42894.603 | BK7: null | BL7: completed | BM7: 0 rows | BN7: 900000 | BO7: 100 | BP7: null | BQ7: a483f3b36f855ce865c9eb2e947927fa8a100130efddfd91a92b222c1b839dac | BR7: 1 | BS7: 2017-06-08 17:02:33.668000 UTC | BT7: TRUE | BU7: null | BV7: FALSE | BW7: null | BX7: 1 | BY7: America/Montevideo | BZ7: completed | CA7: null | CB7: 708 | CC7: 2017-06-08 17:25:54.827000 UTC | CD7: null | CE7: 2017-06-08 17:28:40.885000 UTC | CF7: null | CG7: 2017-06-08 17:28:49.708000 UTC | CH7: null | CI7: 2017-06-08 18:03:43.653000 UTC | CJ7: null | CK7: null | CL7: null | CM7: null | CN7: null | CO7: 1 | CP7: null | CQ7: null | CR7: null | CS7: null | CT7: null | CU7: null | CV7: null | CW7: null | CX7: null | CY7: fccb2bae6bc7253501ebddf5cfe39bc2ba689bd23d32bef1e9867d4c9b26f3a9 | CZ7: completed | DA7: null | DB7: null | DC7: 2017-06-08 18:03:43.650000 UTC | DD7: null | DE7: 1 | DF7: null | DG7: null | DH7: null | DI7: null | DJ7: null | DK7: null | DL7: null | DM7: null | DN7: null | DO7: null | DP7: null | DQ7: TRUE | DR7: TRUE | DS7: 42894.628 | DT7: null | DU7: null | DV7: 0 | DW7: 0 | DX7: null | DY7: null | DZ7: null | EA7: null | EB7: null | EC7: 0 | ED7: FALSE | EE7: FALSE | EF7: null | EG7: 0 | EH7: null | EI7: 0 | EJ7: 0 | EK7: 0 | EL7: 0 | EM7: null | EN7: null | EO7: null | EP7: null | EQ7: 0 | ER7: 0 | ES7: 0 | ET7: 0 | EU7: 0 | EV7: 0 | EW7: 0 | EX7: null | EY7: 42894.585 | EZ7: 42894.601 | FA7: null | FB7: 42894.603 | FC7: null | FD7: 42894.603 | FE7: null | FF7: 42894.628 | FG7: null | FH7: null | FI7: null | FJ7: null | FK7: null | FL7: null | FM7: 1 | FN7: 0 | FO7: null | FP7: null | FQ7: null | FR7: CG2M3HUKIEBYLZXEQOM1TCN3QQUJYQ3DMGJCPFHJ | FS7: 1 | FT7: 42 | FU7: Empanadaspeia | FV7: null | FW7: null | FX7: POINT(-56.1996002197266 -34.9057006835938) | FY7: restaurants | FZ7: null | GA7: null | GB7: null | GC7: 0 | GD7: 1518 | GE7: 29 | GF7: 0 | GG7: null | GH7: 0 | GI7: 0 | GJ7: null | GK7: null | GL7: null | GM7: null | GN7: null | GO7: null | GP7: null | GQ7: null | GR7: null | GS7: null | GT7: null | GU7: null | GV7: null | GW7: 0 | GX7: 0 | GY7: 0 | GZ7: 0 | HA7: null | HB7: 0 | HC7: 0 | HD7: 0 | HE7: 0 | HF7: 0 | HG7: 1800 | HH7: null | HI7: null | HJ7: null | HK7: 0 | HL7: 0 | HM7: 0 | HN7: 0 | HO7: 0 | HP7: 0 | HQ7: 1 | HR7: 42894.628 | HS7: 1 | HT7: 0 | HU7: 1568 | HV7: null | HW7: 45324.94 | HX7: null | HY7: null | HZ7: null
